Workbook

Sheet LeMANS inputs
B1: 9.8765333 | C1: 9.8765333 | D1: 9.8765333 | E1: 9.8765333 | F1: 9.8765333 | G1: 9.8765333 | H1: 9.8765333 | I1: 9.8765333 | J1: 9.8765333 | K1: 9.8765333 | L1: 9.8765333 | M1: 9.8765333 | N1: 9.8765333 | O1: 9.8765333 | P1: 9.8765333 | Q1: binwidth
A2: init n at size
A3: foragefish | B3: 236858.38 | C3: 68707.62 | D3: 3060.0544 | E3: 0 | F3: 0 | G3: 0 | H3: 0 | I3: 0 | J3: 0 | K3: 0 | L3: 0 | M3: 0 | N3: 0 | O3: 0 | P3: 0
A4: spinydog | B4: 0.66268858 | C4: 0.78275415 | D4: 0.6947107 | E4: 0.61053492 | F4: 0.52648703 | G4: 0.44055388 | H4: 0.35183219 | I4: 0.26060896 | J4: 0.16915631 | K4: 0.085657368 | L4: 0.014235365 | M4: 0 | N4: 0 | O4: 0 | P4: 0
A5: winterskate | B5: 1.516425 | C5: 2.3197349 | D5: 2.2095006 | E5: 2.1042627 | F5: 1.9980525 | G5: 1.8843574 | H5: 1.7559598 | I5: 1.6025068 | J5: 1.4068569 | K5: 1.1422229 | L5: 0.78245253 | M5: 0.3491771 | N5: 0 | O5: 0 | P5: 0
A6: littleskate | B6: 2.6402269 | C6: 4.7836717 | D6: 5.3512422 | E6: 6.3066725 | F6: 8.5388107 | G6: 11.161203 | H6: 0 | I6: 0 | J6: 0 | K6: 0 | L6: 0 | M6: 0 | N6: 0 | O6: 0 | P6: 0
A7: Aherring | B7: 80.697299 | C7: 85.853259 | D7: 58.989363 | E7: 30.434226 | F7: 0 | G7: 0 | H7: 0 | I7: 0 | J7: 0 | K7: 0 | L7: 0 | M7: 0 | N7: 0 | O7: 0 | P7: 0
A8: silverhake | B8: 4.4434732 | C8: 5.0468111 | D8: 3.6543024 | E8: 2.5206962 | F8: 1.6896202 | G8: 1.0732097 | H8: 0.5527011 | I8: 0 | J8: 0 | K8: 0 | L8: 0 | M8: 0 | N8: 0 | O8: 0 | P8: 0
A9: Acod | B9: 1.0007063 | C9: 1.469081 | D9: 1.1813408 | E9: 0.94423672 | F9: 0.76798 | G9: 0.63579078 | H9: 0.53201978 | I9: 0.44576677 | J9: 0.37443163 | K9: 0.30532796 | L9: 0.23426737 | M9: 0.16154443 | N9: 0.092194445 | O9: 0.033492511 | P9: 0.0056977634 | R9: max Linf determined n size classes, all other in same
A10: haddock | B10: 4.2530649 | C10: 10.51529 | D10: 10.007216 | E10: 9.5831649 | F10: 9.4794295 | G10: 9.8232772 | H10: 11.135063 | I10: 12.677525 | J10: 0 | K10: 0 | L10: 0 | M10: 0 | N10: 0 | O10: 0 | P10: 0 | R10: =148*1.001 -> 148.148 | S10: maxsize
A11: pollock | B11: 1.341509 | C11: 1.4201613 | D11: 0.99574412 | E11: 0.69141069 | F11: 0.4869821 | G11: 0.34638369 | H11: 0.24514075 | I11: 0.16826285 | J11: 0.11159746 | K11: 0.064711018 | L11: 0.028515388 | M11: 0.005226754 | N11: 0 | O11: 0 | P11: 0 | R11: 15 | S11: nsc | T11: n size classes
A12: redhake | B12: 0.077436746 | C12: 0.096534212 | D12: 0.073053778 | E12: 0.055334251 | F12: 0.042993276 | G12: 0.034149288 | H12: 0.027404153 | I12: 0.021909125 | J12: 0.017356464 | K12: 0.013081142 | L12: 0.0089773971 | M12: 0.0052041523 | N12: 0.0021926492 | O12: 0.00054752054 | P12: 0 | R12: =R10/R11 -> 9.8765333 | S12: 10 cm wide bins (approx)
A13: whitehake | B13: 2.4403647 | C13: 2.7361122 | D13: 1.975782 | E13: 1.3700458 | F13: 0.92987266 | G13: 0.61191444 | H13: 0.14007186 | I13: 0 | J13: 0 | K13: 0 | L13: 0 | M13: 0 | N13: 0 | O13: 0 | P13: 0
A14: fourspotfl | B14: 0.33930842 | C14: 0.57729026 | D14: 0.64836859 | E14: 0.77585505 | F14: 1.2172559 | G14: 0.69835689 | H14: 0 | I14: 0 | J14: 0 | K14: 0 | L14: 0 | M14: 0 | N14: 0 | O14: 0 | P14: 0
A15: summerfl | B15: 0.0018852206 | C15: 0.0039069684 | D15: 0.0038549237 | E15: 0.003832133 | F15: 0.0038114598 | G15: 0.0037756335 | H15: 0.00370799 | I15: 0.0035849627 | J15: 0.0033785349 | K15: 0.0030581133 | L15: 0.0025956259 | M15: 0.0019734295 | N15: 0.0012000765 | O15: 0.0005287084 | P15: 0
A16: yellowtailfl | B16: 3.9070123 | C16: 6.6463913 | D16: 7.4657787 | E16: 8.9445013 | F16: 14.069671 | G16: 8.087008 | H16: 0 | I16: 0 | J16: 0 | K16: 0 | L16: 0 | M16: 0 | N16: 0 | O16: 0 | P16: 0
A17: winterfl | B17: 1.9002648 | C17: 2.8288027 | D17: 3.1164227 | E17: 3.7002457 | F17: 5.300677 | G17: 0 | H17: 0 | I17: 0 | J17: 0 | K17: 0 | L17: 0 | M17: 0 | N17: 0 | O17: 0 | P17: 0
A18: witchfl | B18: 0.45072528 | C18: 0.5772862 | D18: 0.60123768 | E18: 0.95375536 | F18: 0 | G18: 0 | H18: 0 | I18: 0 | J18: 0 | K18: 0 | L18: 0 | M18: 0 | N18: 0 | O18: 0 | P18: 0
A19: windowpane | B19: 5.2640646 | C19: 6.9965953 | D19: 7.4158645 | E19: 8.8555641 | F19: 5.1889052 | G19: 0 | H19: 0 | I19: 0 | J19: 0 | K19: 0 | L19: 0 | M19: 0 | N19: 0 | O19: 0 | P19: 0
A20: Amackerel | B20: 5.678337 | C20: 7.2383546 | D20: 6.5280456 | E20: 5.8381126 | F20: 5.2898121 | G20: 0 | H20: 0 | I20: 0 | J20: 0 | K20: 0 | L20: 0 | M20: 0 | N20: 0 | O20: 0 | P20: 0
A21: longhornsculpin | B21: 6.9553931 | C21: 16.030154 | D21: 32.592999 | E21: 22.866495 | F21: 0 | G21: 0 | H21: 0 | I21: 0 | J21: 0 | K21: 0 | L21: 0 | M21: 0 | N21: 0 | O21: 0 | P21: 0
A22: searaven | B22: 0 | C22: 0.043707993 | D22: 0.049044867 | E22: 0.056932844 | F22: 0.07039137 | G22: 0.099115138 | H22: 0.39068344 | I22: 0 | J22: 0 | K22: 0 | L22: 0 | M22: 0 | N22: 0 | O22: 0 | P22: 0
A23: goosefish | B23: 0.14683387 | C23: 0.19944634 | D23: 0.18371622 | E23: 0.16863678 | F23: 0.15346564 | G23: 0.13773194 | H23: 0.12109972 | I23: 0.10330729 | J23: 0.084151179 | K23: 0.063570465 | L23: 0.042037881 | M23: 0.021529943 | N23: 0.0072207089 | O23: 0 | P23: 0
A24: sandlance | B24: 129.08035 | C24: 175.26245 | D24: 118.31115 | E24: 0 | F24: 0 | G24: 0 | H24: 0 | I24: 0 | J24: 0 | K24: 0 | L24: 0 | M24: 0 | N24: 0 | O24: 0 | P24: 0
A26: params | B26: vonB_k | C26: Linf | D26: Lmat | E26: kappamat | F26: lwt_a | G26: lwt_b | H26: maxSSB | I26: fished? | J26: inMSprod | K26: maxsize | M26: use
A27: foragefish | B27: 0.1 | C27: 20 | D27: 13 | E27: 0.587 | F27: 0.005 | G27: 3 | H27: 5000 | I27: 0 | J27: 0 | K27: =C27*1.01 -> 20.2 | M27: 0
A28: spinydog | B28: 0.1 | C28: 99.99 | D28: 79.99 | E28: 0.587 | F28: 0.003 | G28: 3.122 | H28: 16.125 | I28: 1 | J28: 1 | K28: =C28*1.01 -> 100.9899 | M28: 1
A29: winterskate | B29: 0.14405 | C29: 114.1 | D29: 85 | E29: 0.587 | F29: 0.004 | G29: 3.317 | H29: 83.96 | I29: 1 | J29: agg | K29: =C29*1.01 -> 115.241 | M29: 1
A30: littleskate | B30: 0.352 | C30: 53 | D30: 49.99 | E30: 0.587 | F30: 0.005 | G30: 3.141 | H30: 24.51 | I30: 1 | J30: agg | K30: =C30*1.01 -> 53.53 | M30: 0
A31: Aherring | B31: 0.28 | C31: 34.99 | D31: 25 | E31: 0.587 | F31: 0.01 | G31: 2.99 | H31: 101.91 | I31: 1 | J31: 1 | K31: =C31*1.01 -> 35.3399 | M31: 1
A32: silverhake | B32: 0.18 | C32: 65.4 | D32: 23 | E32: 0.587 | F32: 0.007 | G32: 3.05 | H32: 25.8 | I32: 1 | J32: 0 | K32: =C32*1.01 -> 66.054 | M32: 0
A33: Acod | B33: 0.12 | C33: 148 | D33: 39.99 | E33: 0.149 | F33: 0.009 | G33: 3.052 | H33: 71.17 | I33: 1 | J33: 1 | K33: =C33*1.01 -> 149.48 | M33: 1
A34: haddock | B34: 0.376 | C34: 73.8 | D34: 28 | E34: 0.3745 | F34: 0.01 | G34: 3.068 | H34: 250.69 | I34: 1 | J34: 1 | K34: =C34*1.01 -> 74.538 | M34: 1
A35: pollock | B35: 0.1 | C35: 111 | D35: 39.99 | E35: 0.154 | F35: 0.01 | G35: 3.028 | H35: 27.31 | I35: 1 | J35: 0 | K35: =C35*1.01 -> 112.11 | M35: 0
A36: redhake | B36: 0.106 | C36: 136 | D36: 34 | E36: 0.137 | F36: 0.006 | G36: 3.22 | H36: 3.01 | I36: 1 | J36: 0 | K36: =C36*1.01 -> 137.36 | M36: 0
A37: whitehake | B37: 0.19 | C37: 60.2 | D37: 25 | E37: 0.507 | F37: 0.005 | G37: 3.222 | H37: 10.75 | I37: 1 | J37: 0 | K37: =C37*1.01 -> 60.802 | M37: 0
A38: fourspotfl | B38: 0.335 | C38: 49.99 | D38: 25 | E38: 0.306 | F38: 0.008 | G38: 3 | H38: 2.58 | I38: 1 | J38: 0 | K38: =C38*1.01 -> 50.4899 | M38: 0
A39: summerfl | B39: 0.173 | C39: 137 | D39: 26 | E39: 0.306 | F39: 0.007 | G39: 3.278 | H39: 0.43 | I39: 1 | J39: 0 | K39: =C39*1.01 -> 138.37 | M39: 0
A40: yellowtailfl | B40: 0.335 | C40: 49.99 | D40: 23 | E40: 0.487 | F40: 0.008 | G40: 3.129 | H40: 48.16 | I40: 1 | J40: 1 | K40: =C40*1.01 -> 50.4899 | M40: 1
A41: winterfl | B41: 0.283 | C41: 45.5 | D41: 25 | E41: 0.587 | F41: 0.011 | G41: 3.138 | H41: 13.33 | I41: 1 | J41: 1 | K41: =C41*1.01 -> 45.955 | M41: 1
...

Sheet just10_firsttry
B1: 9.8765333 | C1: 9.8765333 | D1: 9.8765333 | E1: 9.8765333 | F1: 9.8765333 | G1: 9.8765333 | H1: 9.8765333 | I1: 9.8765333 | J1: 9.8765333 | K1: 9.8765333 | L1: 9.8765333 | M1: 9.8765333 | N1: 9.8765333 | O1: 9.8765333 | P1: 9.8765333 | Q1: binwidth | R1: max Linf determined n size classes, all other in same
A2: init n at size | B2: 10 | C2: 20 | D2: 30 | E2: 40 | F2: 50 | G2: 60 | H2: 70 | I2: 80 | J2: 90 | K2: 100 | L2: 110 | M2: 120 | N2: 130 | O2: 140 | P2: 150 | Q2: use | R2: =148*1.001 -> 148.148 | S2: maxsize
A3: spinydog | B3: 0.66268858 | C3: 0.78275415 | D3: 0.6947107 | E3: 0.61053492 | F3: 0.52648703 | G3: 0.44055388 | H3: 0.35183219 | I3: 0.26060896 | J3: 0.16915631 | K3: 0.085657368 | L3: 0.014235365 | M3: 0 | N3: 0 | O3: 0 | P3: 0 | Q3: 1 | R3: 15 | S3: nsc | T3: n size classes
A4: winterskate | B4: 1.516425 | C4: 2.3197349 | D4: 2.2095006 | E4: 2.1042627 | F4: 1.9980525 | G4: 1.8843574 | H4: 1.7559598 | I4: 1.6025068 | J4: 1.4068569 | K4: 1.1422229 | L4: 0.78245253 | M4: 0.3491771 | N4: 0 | O4: 0 | P4: 0 | Q4: 1 | R4: =R2/R3 -> 9.8765333 | S4: 10 cm wide bins (approx)
A5: Aherring | B5: 80.697299 | C5: 85.853259 | D5: 58.989363 | E5: 30.434226 | F5: 0 | G5: 0 | H5: 0 | I5: 0 | J5: 0 | K5: 0 | L5: 0 | M5: 0 | N5: 0 | O5: 0 | P5: 0 | Q5: 1
A6: Acod | B6: 1.0007063 | C6: 1.469081 | D6: 1.1813408 | E6: 0.94423672 | F6: 0.76798 | G6: 0.63579078 | H6: 0.53201978 | I6: 0.44576677 | J6: 0.37443163 | K6: 0.30532796 | L6: 0.23426737 | M6: 0.16154443 | N6: 0.092194445 | O6: 0.033492511 | P6: 0.0056977634 | Q6: 1
A7: haddock | B7: 4.2530649 | C7: 10.51529 | D7: 10.007216 | E7: 9.5831649 | F7: 9.4794295 | G7: 9.8232772 | H7: 11.135063 | I7: 12.677525 | J7: 0 | K7: 0 | L7: 0 | M7: 0 | N7: 0 | O7: 0 | P7: 0 | Q7: 1
A8: yellowtailfl | B8: 3.9070123 | C8: 6.6463913 | D8: 7.4657787 | E8: 8.9445013 | F8: 14.069671 | G8: 8.087008 | H8: 0 | I8: 0 | J8: 0 | K8: 0 | L8: 0 | M8: 0 | N8: 0 | O8: 0 | P8: 0 | Q8: 1
A9: winterfl | B9: 1.9002648 | C9: 2.8288027 | D9: 3.1164227 | E9: 3.7002457 | F9: 5.300677 | G9: 0 | H9: 0 | I9: 0 | J9: 0 | K9: 0 | L9: 0 | M9: 0 | N9: 0 | O9: 0 | P9: 0 | Q9: 1
A10: Amackerel | B10: 5.678337 | C10: 7.2383546 | D10: 6.5280456 | E10: 5.8381126 | F10: 5.2898121 | G10: 0 | H10: 0 | I10: 0 | J10: 0 | K10: 0 | L10: 0 | M10: 0 | N10: 0 | O10: 0 | P10: 0 | Q10: 1
A11: searaven | B11: 0 | C11: 0.043707993 | D11: 0.049044867 | E11: 0.056932844 | F11: 0.07039137 | G11: 0.099115138 | H11: 0.39068344 | I11: 0 | J11: 0 | K11: 0 | L11: 0 | M11: 0 | N11: 0 | O11: 0 | P11: 0 | Q11: 1 | X11: a | Y11: b
A12: sandlance | B12: 129.08035 | C12: 175.26245 | D12: 118.31115 | E12: 0 | F12: 0 | G12: 0 | H12: 0 | I12: 0 | J12: 0 | K12: 0 | L12: 0 | M12: 0 | N12: 0 | O12: 0 | P12: 0 | Q12: 1 | U12: need to fit to maturity data | X12: propmat=1/(1+exp(-(mat_nu+mat_omega*lbinmidpt)))
N13: binwidth | U13: used as first approximations | X13: mat dat Obrien et al 1993 (avg male and female)
A14: params | B14: vonB_k | C14: Linf | D14: L50mat | E14: kappamat | F14: lwt_a | G14: lwt_b | H14: maxSSB | I14: fished? | J14: inMSprod | K14: maxsize | L14: maxbin | M14: use | T14: L50matbin | U14: mat_nu | V14: mat_omega | X14: mat_nu | Y14: mat_omega
A15: spinydog | B15: 0.1 | C15: 99.99 | D15: 79.99 | E15: 0.587 | F15: 0.003 | G15: 3.122 | H15: 16.125 | I15: 1 | J15: 1 | K15: =C15*1.01 -> 100.9899 | L15: =SUM(N15:R15) -> 110 | M15: 1 | N15: 20 | O15: 20 | P15: 20 | Q15: 20 | R15: 30 | T15: 4 | U15: -5 | V15: 0.1 | W15: spinydog
A16: winterskate | B16: 0.14405 | C16: 114.1 | D16: 85 | E16: 0.587 | F16: 0.004 | G16: 3.317 | H16: 83.96 | I16: 1 | J16: agg | K16: =C16*1.01 -> 115.241 | L16: =SUM(N16:R16) -> 120 | M16: 1 | N16: 20 | O16: 20 | P16: 20 | Q16: 20 | R16: 40 | T16: 5 | U16: -5 | V16: 0.1 | W16: winterskate
A17: Aherring | B17: 0.28 | C17: 34.99 | D17: 25 | E17: 0.587 | F17: 0.01 | G17: 2.99 | H17: 101.91 | I17: 1 | J17: 1 | K17: =C17*1.01 -> 35.3399 | L17: =SUM(N17:R17) -> 40 | M17: 1 | N17: 5 | O17: 5 | P17: 10 | Q17: 10 | R17: 10 | T17: 5 | U17: -5 | V17: 0.2 | W17: Aherring | X17: =AVERAGE(-28.484,-40.461) -> -34.4725 | Y17: =AVERAGE(1.123,1.597) -> 1.36
A18: Acod | B18: 0.12 | C18: 148 | D18: 39.99 | E18: 0.149 | F18: 0.009 | G18: 3.052 | H18: 71.17 | I18: 1 | J18: 1 | K18: =C18*1.01 -> 149.48 | L18: =SUM(N18:R18) -> 150 | M18: 1 | N18: 20 | O18: 20 | P18: 20 | Q18: 40 | R18: 50 | T18: 3 | U18: -5 | V18: 0.16 | W18: Acod | X18: =AVERAGE(-4.932,-5.688) -> -5.31 | Y18: =AVERAGE(0.127,0.139) -> 0.133 | Z18: GB
A19: haddock | B19: 0.376 | C19: 73.8 | D19: 28 | E19: 0.3745 | F19: 0.01 | G19: 3.068 | H19: 250.69 | I19: 1 | J19: 1 | K19: =C19*1.01 -> 74.538 | L19: =SUM(N19:R19) -> 80 | M19: 1 | N19: 10 | O19: 10 | P19: 20 | Q19: 20 | R19: 20 | T19: 3 | U19: -5 | V19: 0.13 | W19: haddock | X19: =AVERAGE(-6.252,-5.064) -> -5.658 | Y19: =AVERAGE(0.21,0.189) -> 0.1995 | Z19: GB
A20: yellowtailfl | B20: 0.335 | C20: 49.99 | D20: 23 | E20: 0.487 | F20: 0.008 | G20: 3.129 | H20: 48.16 | I20: 1 | J20: 1 | K20: =C20*1.01 -> 50.4899 | L20: =SUM(N20:R20) -> 60 | M20: 1 | N20: 10 | O20: 10 | P20: 10 | Q20: 10 | R20: 20 | T20: 3 | U20: -5 | V20: 0.2 | W20: yellowtailfl | X20: =AVERAGE(-15.136,-8.145) -> -11.6405 | Y20: =AVERAGE(0.587,0.381) -> 0.484 | Z20: GB
A21: winterfl | B21: 0.283 | C21: 45.5 | D21: 25 | E21: 0.587 | F21: 0.011 | G21: 3.138 | H21: 13.33 | I21: 1 | J21: 1 | K21: =C21*1.01 -> 45.955 | L21: =SUM(N21:R21) -> 50 | M21: 1 | N21: 10 | O21: 10 | P21: 10 | Q21: 10 | R21: 10 | T21: 3 | U21: -5 | V21: 0.2 | W21: winterfl | X21: =AVERAGE(-10.855,-7.724) -> -9.2895 | Y21: =AVERAGE(0.436,0.301) -> 0.3685 | Z21: GB
A22: Amackerel | B22: 0.243 | C22: 46.1 | D22: 29.99 | E22: 0.641 | F22: 0.007 | G22: 3.319 | H22: 23.87 | I22: 1 | J22: 1 | K22: =C22*1.01 -> 46.561 | L22: =SUM(N22:R22) -> 50 | M22: 1 | N22: 10 | O22: 10 | P22: 10 | Q22: 10 | R22: 10 | T22: 3 | U22: -5 | V22: 0.2 | W22: Amackerel | X22: =AVERAGE(-16.475,-17.102) -> -16.7885 | Y22: =AVERAGE(0.641,0.658) -> 0.6495
A23: searaven | B23: 0.72 | C23: 68 | D23: 25 | E23: 0.587 | F23: 0.019 | G23: 3.1 | H23: 3.225 | I23: 0 | J23: 0 | K23: =C23*1.01 -> 68.68 | L23: =SUM(N23:R23) -> 70 | M23: 1 | N23: 10 | O23: 10 | P23: 10 | Q23: 20 | R23: 20 | T23: 3 | U23: -5 | V23: 0.2 | W23: searaven
A24: sandlance | B24: 0.5 | C24: 24 | D24: 12 | E24: 0.587 | F24: 0.003 | G24: 3.211 | H24: 83.21 | I24: 0 | J24: 0 | K24: =C24*1.01 -> 24.24 | L24: =SUM(N24:R24) -> 30 | M24: 1 | N24: 5 | O24: 5 | P24: 5 | Q24: 5 | R24: 10 | T24: 5 | U24: -5 | V24: 0.3 | W24: sandlance
O25: for smaller bins, divide in half to approximate | X25: used these from Obrien
O26: Initial n at size (sum bins above assuming they are 10 cm)
A27: foodweb | B27: preds-> | O27: bin1 | P27: bin2 | Q27: bin3 | R27: bin4 | S27: bin5
A28: prey | B28: spinydog | C28: winterskate | D28: Aherring | E28: Acod | F28: haddock | G28: yellowtailfl | H28: winterfl | I28: Amackerel | J28: searaven | K28: sandlance | N28: spinydog | O28: =SUM(B3:C3) -> 1.4454427 | P28: =SUM(D3:E3) -> 1.3052456 | Q28: =SUM(F3:G3) -> 0.96704091 | R28: =SUM(H3:I3) -> 0.61244115 | S28: =SUM(J3:L3) -> 0.26904904
A29: spinydog | B29: 1 | C29: 0 | D29: 0 | E29: 0 | F29: 0 | G29: 0 | H29: 0 | I29: 0 | J29: 0 | K29: 0 | N29: winterskate | O29: =SUM(B4:C4) -> 3.8361599 | P29: =SUM(D4:E4) -> 4.3137633 | Q29: =SUM(F4:G4) -> 3.8824099 | R29: =SUM(H4:I4) -> 3.3584666 | S29: =SUM(J4:M4) -> 3.6807094
A30: winterskate | B30: 1 | C30: 0 | D30: 0 | E30: 0 | F30: 0 | G30: 0 | H30: 0 | I30: 0 | J30: 0 | K30: 0 | N30: Aherring | O30: =B5/2 -> 40.34865 | P30: =B5/2 -> 40.34865 | Q30: =C5 -> 85.853259 | R30: =D5 -> 58.989363 | S30: =E5 -> 30.434226
A31: Aherring | B31: 1 | C31: 1 | D31: 0 | E31: 1 | F31: 1 | G31: 0 | H31: 0 | I31: 0 | J31: 1 | K31: 0 | N31: Acod | O31: =B6+C6 -> 2.4697873 | P31: =D6+E6 -> 2.1255775 | Q31: =SUM(F6:G6) -> 1.4037708 | R31: =SUM(H6:K6) -> 1.6575461 | S31: =SUM(L6:P6) -> 0.52719652
A32: Acod | B32: 1 | C32: 1 | D32: 0 | E32: 1 | F32: 1 | G32: 0 | H32: 0 | I32: 0 | J32: 1 | K32: 0 | N32: haddock | O32: =B7 -> 4.2530649 | P32: =C7 -> 10.51529 | Q32: =SUM(D7:E7) -> 19.590381 | R32: =SUM(F7:G7) -> 19.302707 | S32: =SUM(H7:I7) -> 23.812588
A33: haddock | B33: 1 | C33: 1 | D33: 0 | E33: 0 | F33: 1 | G33: 0 | H33: 0 | I33: 0 | J33: 1 | K33: 0 | N33: yellowtailfl | O33: =B8 -> 3.9070123 | P33: =C8 -> 6.6463913 | Q33: =D8 -> 7.4657787 | R33: =E8 -> 8.9445013 | S33: =SUM(F8:G8) -> 22.156679
A34: yellowtailfl | B34: 1 | C34: 0 | D34: 0 | E34: 0 | F34: 0 | G34: 0 | H34: 0 | I34: 0 | J34: 0 | K34: 0 | N34: winterfl | O34: =B9 -> 1.9002648 | P34: =C9 -> 2.8288027 | Q34: =D9 -> 3.1164227 | R34: =E9 -> 3.7002457 | S34: =F9 -> 5.300677
A35: winterfl | B35: 1 | C35: 0 | D35: 0 | E35: 0 | F35: 0 | G35: 0 | H35: 0 | I35: 0 | J35: 0 | K35: 0 | N35: Amackerel | O35: =B10 -> 5.678337 | P35: =C10 -> 7.2383546 | Q35: =D10 -> 6.5280456 | R35: =E10 -> 5.8381126 | S35: =F10 -> 5.2898121
A36: Amackerel | B36: 1 | C36: 1 | D36: 0 | E36: 1 | F36: 0 | G36: 0 | H36: 0 | I36: 0 | J36: 0 | K36: 0 | N36: searaven | O36: 0.001 | P36: =C11 -> 0.043707993 | Q36: =D11 -> 0.049044867 | R36: =SUM(E11:F11) -> 0.12732421 | S36: =SUM(G11:H11) -> 0.48979858 | T36: changed sea raven bin 1 to be non zero
A37: searaven | B37: 0 | C37: 1 | D37: 0 | E37: 0 | F37: 0 | G37: 0 | H37: 0 | I37: 0 | J37: 0 | K37: 0 | N37: sandlance | O37: =B12/2 -> 64.540175 | P37: 64.540175 | Q37: =C12/2 -> 87.631225 | R37: 87.631225 | S37: =D12 -> 118.31115
A38: sandlance | B38: 1 | C38: 1 | D38: 1 | E38: 1 | F38: 1 | G38: 1 | H38: 1 | I38: 1 | J38: 1 | K38: 0
N39: N_mult | O39: 3046527 | P39: convert catch per tow to total N (from Jason's data) used in LeMANS
B40: fecundity=theta*(d*lbinmidpt^h)
...

Sheet just10_newset_hydra_sim_GB
B1: 9.8765333 | C1: 9.8765333 | D1: 9.8765333 | E1: 9.8765333 | F1: 9.8765333 | G1: 9.8765333 | H1: 9.8765333 | I1: 9.8765333 | J1: 9.8765333 | K1: 9.8765333 | L1: 9.8765333 | M1: 9.8765333 | N1: 9.8765333 | O1: 9.8765333 | P1: 9.8765333 | Q1: binwidth | R1: max Linf determined n size classes, all other in same
A2: init n at size | B2: 10 | C2: 20 | D2: 30 | E2: 40 | F2: 50 | G2: 60 | H2: 70 | I2: 80 | J2: 90 | K2: 100 | L2: 110 | M2: 120 | N2: 130 | O2: 140 | P2: 150 | Q2: use | R2: =148*1.001 -> 148.148 | S2: maxsize
A3: spinydog | B3: 0.66268858 | C3: 0.78275415 | D3: 0.6947107 | E3: 0.61053492 | F3: 0.52648703 | G3: 0.44055388 | H3: 0.35183219 | I3: 0.26060896 | J3: 0.16915631 | K3: 0.085657368 | L3: 0.014235365 | M3: 0 | N3: 0 | O3: 0 | P3: 0 | Q3: 1 | R3: 15 | S3: nsc | T3: n size classes
A4: winterskate | B4: 1.516425 | C4: 2.3197349 | D4: 2.2095006 | E4: 2.1042627 | F4: 1.9980525 | G4: 1.8843574 | H4: 1.7559598 | I4: 1.6025068 | J4: 1.4068569 | K4: 1.1422229 | L4: 0.78245253 | M4: 0.3491771 | N4: 0 | O4: 0 | P4: 0 | Q4: 1 | R4: =R2/R3 -> 9.8765333 | S4: 10 cm wide bins (approx)
A5: littleskate | B5: 2.6402269 | C5: 4.7836717 | D5: 5.3512422 | E5: 6.3066725 | F5: 8.5388107 | G5: 11.161203 | H5: 0 | I5: 0 | J5: 0 | K5: 0 | L5: 0 | M5: 0 | N5: 0 | O5: 0 | P5: 0
A6: winter+little | B6: =SUM(B4:B5) -> 4.1566519 | C6: =SUM(C4:C5) -> 7.1034066 | D6: =SUM(D4:D5) -> 7.5607428 | E6: =SUM(E4:E5) -> 8.4109352 | F6: =SUM(F4:F5) -> 10.536863 | G6: =SUM(G4:G5) -> 13.04556 | H6: =SUM(H4:H5) -> 1.7559598 | I6: =SUM(I4:I5) -> 1.6025068 | ... P6: =SUM(P4:P5) -> 0 | R6: simple sum of winter plus little--a pain for all other pars, keep just winter right now
A7: Aherring | B7: 80.697299 | C7: 85.853259 | D7: 58.989363 | E7: 30.434226 | F7: 0 | G7: 0 | H7: 0 | I7: 0 | J7: 0 | K7: 0 | L7: 0 | M7: 0 | N7: 0 | O7: 0 | P7: 0 | Q7: 1
A8: Acod | B8: 1.0007063 | C8: 1.469081 | D8: 1.1813408 | E8: 0.94423672 | F8: 0.76798 | G8: 0.63579078 | H8: 0.53201978 | I8: 0.44576677 | J8: 0.37443163 | K8: 0.30532796 | L8: 0.23426737 | M8: 0.16154443 | N8: 0.092194445 | O8: 0.033492511 | P8: 0.0056977634 | Q8: 1
A9: haddock | B9: 4.2530649 | C9: 10.51529 | D9: 10.007216 | E9: 9.5831649 | F9: 9.4794295 | G9: 9.8232772 | H9: 11.135063 | I9: 12.677525 | J9: 0 | K9: 0 | L9: 0 | M9: 0 | N9: 0 | O9: 0 | P9: 0 | Q9: 1
A10: yellowtailfl | B10: 3.9070123 | C10: 6.6463913 | D10: 7.4657787 | E10: 8.9445013 | F10: 14.069671 | G10: 8.087008 | H10: 0 | I10: 0 | J10: 0 | K10: 0 | L10: 0 | M10: 0 | N10: 0 | O10: 0 | P10: 0 | Q10: 1
A11: winterfl | B11: 1.9002648 | C11: 2.8288027 | D11: 3.1164227 | E11: 3.7002457 | F11: 5.300677 | G11: 0 | H11: 0 | I11: 0 | J11: 0 | K11: 0 | L11: 0 | M11: 0 | N11: 0 | O11: 0 | P11: 0 | Q11: 1
A12: Amackerel | B12: 5.678337 | C12: 7.2383546 | D12: 6.5280456 | E12: 5.8381126 | F12: 5.2898121 | G12: 0 | H12: 0 | I12: 0 | J12: 0 | K12: 0 | L12: 0 | M12: 0 | N12: 0 | O12: 0 | P12: 0 | Q12: 1
A13: silverhake | B13: 4.4434732 | C13: 5.0468111 | D13: 3.6543024 | E13: 2.5206962 | F13: 1.6896202 | G13: 1.0732097 | H13: 0.5527011 | I13: 0 | J13: 0 | K13: 0 | L13: 0 | M13: 0 | N13: 0 | O13: 0 | P13: 0 | Q13: 1 | X13: a | Y13: b
A14: goosefish | B14: 0.14683387 | C14: 0.19944634 | D14: 0.18371622 | E14: 0.16863678 | F14: 0.15346564 | G14: 0.13773194 | H14: 0.12109972 | I14: 0.10330729 | J14: 0.084151179 | K14: 0.063570465 | L14: 0.042037881 | M14: 0.021529943 | N14: 0.0072207089 | O14: 0 | P14: 0 | Q14: 1 | U14: need to fit to maturity data | X14: propmat=1/(1+exp(-(mat_nu+mat_omega*lbinmidpt)))
N15: binwidth | U15: used as first approximations | X15: mat dat Obrien et al 1993 (avg male and female)
A16: params | B16: vonB_k* | C16: Linf* | D16: L50mat | E16: kappamat | F16: lwt_a | G16: lwt_b | H16: maxSSB | I16: fished? | J16: inMSprod | K16: maxsize | L16: maxbin | M16: use | T16: L50matbin | U16: mat_nu | V16: mat_omega | X16: mat_nu | Y16: mat_omega | AA16: L50mat
A17: spinydog | B17: 0.1 | C17: 99.99 | D17: 79.99 | E17: 0.587 | F17: 0.003 | G17: 3.122 | H17: 16.125 | I17: 1 | J17: 1 | K17: =C17*1.01 -> 100.9899 | L17: =SUM(N17:R17) -> 110 | M17: 1 | N17: 20 | O17: 20 | P17: 20 | Q17: 20 | R17: 30 | T17: 4 | U17: -5 | V17: 0.1 | W17: spinydog
A18: winterskate | B18: 0.14405 | C18: 114.1 | D18: 85 | E18: 0.587 | F18: 0.004 | G18: 3.317 | H18: 83.96 | I18: 1 | J18: agg | K18: =C18*1.01 -> 115.241 | L18: =SUM(N18:R18) -> 120 | M18: 1 | N18: 20 | O18: 20 | P18: 20 | Q18: 20 | R18: 40 | T18: 5 | U18: -5 | V18: 0.1 | W18: winterskate
A19: Aherring | B19: 0.28 | C19: 34.99 | D19: 25 | E19: 0.587 | F19: 0.01 | G19: 2.99 | H19: 101.91 | I19: 1 | J19: 1 | K19: =C19*1.01 -> 35.3399 | L19: =SUM(N19:R19) -> 40 | M19: 1 | N19: 5 | O19: 5 | P19: 5 | Q19: 5 | R19: 20 | T19: 5 | U19: -5 | V19: 0.2 | W19: Aherring | X19: =AVERAGE(-28.484,-40.461) -> -34.4725 | Y19: =AVERAGE(1.123,1.597) -> 1.36 | Z19: All | AA19: =AVERAGE(25.4,25.3) -> 25.35
A20: Acod | B20: 0.12 | C20: 148 | D20: 39.99 | E20: 0.149 | F20: 0.009 | G20: 3.052 | H20: 71.17 | I20: 1 | J20: 1 | K20: =C20*1.01 -> 149.48 | L20: =SUM(N20:R20) -> 150 | M20: 1 | N20: 20 | O20: 20 | P20: 20 | Q20: 40 | R20: 50 | T20: 3 | U20: -5 | V20: 0.16 | W20: Acod | X20: =AVERAGE(-4.932,-5.688) -> -5.31 | Y20: =AVERAGE(0.127,0.139) -> 0.133 | Z20: GB | AA20: =AVERAGE(38.8,41) -> 39.9
A21: haddock | B21: 0.376 | C21: 73.8 | D21: 28 | E21: 0.3745 | F21: 0.01 | G21: 3.068 | H21: 250.69 | I21: 1 | J21: 1 | K21: =C21*1.01 -> 74.538 | L21: =SUM(N21:R21) -> 80 | M21: 1 | N21: 10 | O21: 10 | P21: 20 | Q21: 20 | R21: 20 | T21: 3 | U21: -5 | V21: 0.13 | W21: haddock | X21: =AVERAGE(-6.252,-5.064) -> -5.658 | Y21: =AVERAGE(0.21,0.189) -> 0.1995 | Z21: GB | AA21: =AVERAGE(29.7,26.8) -> 28.25
A22: yellowtailfl | B22: 0.335 | C22: 49.99 | D22: 23 | E22: 0.487 | F22: 0.008 | G22: 3.129 | H22: 48.16 | I22: 1 | J22: 1 | K22: =C22*1.01 -> 50.4899 | L22: =SUM(N22:R22) -> 60 | M22: 1 | N22: 10 | O22: 10 | P22: 10 | Q22: 10 | R22: 20 | T22: 3 | U22: -5 | V22: 0.2 | W22: yellowtailfl | X22: =AVERAGE(-15.136,-8.145) -> -11.6405 | Y22: =AVERAGE(0.587,0.381) -> 0.484 | Z22: GB | AA22: =AVERAGE(25.8, 21.4) -> 23.6
A23: winterfl | B23: 0.283 | C23: 45.5 | D23: 25 | E23: 0.587 | F23: 0.011 | G23: 3.138 | H23: 13.33 | I23: 1 | J23: 1 | K23: =C23*1.01 -> 45.955 | L23: =SUM(N23:R23) -> 50 | M23: 1 | N23: 10 | O23: 10 | P23: 10 | Q23: 10 | R23: 10 | T23: 3 | U23: -5 | V23: 0.2 | W23: winterfl | X23: =AVERAGE(-10.855,-7.724) -> -9.2895 | Y23: =AVERAGE(0.436,0.301) -> 0.3685 | Z23: GB | AA23: =AVERAGE(24.9,25.6) -> 25.25
A24: Amackerel | B24: 0.243 | C24: 46.1 | D24: 29.99 | E24: 0.641 | F24: 0.007 | G24: 3.319 | H24: 23.87 | I24: 1 | J24: 1 | K24: =C24*1.01 -> 46.561 | L24: =SUM(N24:R24) -> 50 | M24: 1 | N24: 10 | O24: 10 | P24: 10 | Q24: 10 | R24: 10 | T24: 3 | U24: -5 | V24: 0.2 | W24: Amackerel | X24: =AVERAGE(-16.475,-17.102) -> -16.7885 | Y24: =AVERAGE(0.641,0.658) -> 0.6495 | Z24: All | AA24: =AVERAGE(25.7,26) -> 25.85
A25: silverhake | B25: 0.18 | C25: 65.4 | D25: 23 | E25: 0.587 | F25: 0.007 | G25: 3.05 | H25: 25.8 | I25: 1 | J25: 0 | K25: =C25*1.01 -> 66.054 | L25: =SUM(N25:R25) -> 70 | M25: 1 | N25: 10 | O25: 10 | P25: 10 | Q25: 10 | R25: 30 | T25: 3 | U25: -5 | V25: 0.2 | W25: silverhake | X25: =AVERAGE(-11.963, -14.369) -> -13.166 | Y25: =AVERAGE(0.519, 0.646) -> 0.5825 | Z25: GOMNGB | AA25: =AVERAGE(23.1, 22.3) -> 22.7 | AB25: silver hake stock also splits GB in half. Using northern which includes GOM
A26: goosefish | B26: 0.108 | C26: 126 | D26: 49 | E26: 0.587 | F26: 0.02 | G26: 2.897 | H26: 6.45 | I26: 1 | J26: 0 | K26: =C26*1.01 -> 127.26 | L26: =SUM(N26:R26) -> 130 | M26: 1 | N26: 20 | O26: 20 | P26: 20 | Q26: 30 | R26: 40 | T26: 2 | U26: -5 | V26: 0.3 | W26: goosefish | X26: =AVERAGE(-9.765, -11.571) -> -10.668 | Y26: =AVERAGE(0.252,0.325) -> 0.2885 | Z26: NMA | AA26: =AVERAGE(38.8, 35.6) -> 37.2 | AB26: Richards et al 2008 | AD26: averaging M and F probably makes no sense
A27: littleskate | B27: 0.352 | C27: 53 | D27: 49.99 | E27: 0.587 | F27: 0.005 | G27: 3.141 | H27: 24.51 | I27: 1 | J27: agg | K27: =C27*1.01 -> 53.53 | L27: not using | AB27: goosefish >70 cm all F? (size specific sex ratio needed in code?)
B28: *use my fitted parameters instead--see Gblenage_growthpars.csv, changes in red to accommodate reduced growth for herring, silverhake | O28: for smaller bins, divide in half to approximate | X28: used these from Obrien | AB28: also, goosefish stock structure splits GB in half. Awesome.
O29: Initial n at size (sum bins above assuming they are 10 cm) | AB29: using Northern goosefish stock info (includes GOM).
A30: foodweb | B30: preds-> | O30: bin1 | P30: bin2 | Q30: bin3 | R30: bin4 | S30: bin5
A31: prey | B31: spinydog | C31: winterskate | D31: Aherring | E31: Acod | F31: haddock | G31: yellowtailfl | H31: winterfl | I31: Amackerel | J31: silverhake | K31: goosefish | N31: spinydog | O31: =SUM(B3:C3) -> 1.4454427 | P31: =SUM(D3:E3) -> 1.3052456 | Q31: =SUM(F3:G3) -> 0.96704091 | R31: =SUM(H3:I3) -> 0.61244115 | S31: =SUM(J3:L3) -> 0.26904904
A32: spinydog | B32: 1 | C32: 0 | D32: 0 | E32: 0 | F32: 0 | G32: 0 | H32: 0 | I32: 0 | J32: 0 | K32: 1 | N32: winterskate | O32: =SUM(B4:C4) -> 3.8361599 | P32: =SUM(D4:E4) -> 4.3137633 | Q32: =SUM(F4:G4) -> 3.8824099 | R32: =SUM(H4:I4) -> 3.3584666 | S32: =SUM(J4:M4) -> 3.6807094
A33: winterskate | B33: 1 | C33: 0 | D33: 0 | E33: 0 | F33: 0 | G33: 0 | H33: 0 | I33: 0 | J33: 0 | K33: 0 | N33: Aherring | O33: =B7/2 -> 40.34865 | P33: =B7/2 -> 40.34865 | Q33: =C7/2 -> 42.926629 | R33: =C7/2 -> 42.926629 | S33: =D7+E7 -> 89.423589
A34: Aherring | B34: 1 | C34: 1 | D34: 0 | E34: 1 | F34: 1 | G34: 0 | H34: 0 | I34: 0 | J34: 1 | K34: 1 | N34: Acod | O34: =B8+C8 -> 2.4697873 | P34: =D8+E8 -> 2.1255775 | Q34: =SUM(F8:G8) -> 1.4037708 | R34: =SUM(H8:K8) -> 1.6575461 | S34: =SUM(L8:P8) -> 0.52719652
A35: Acod | B35: 1 | C35: 1 | D35: 0 | E35: 1 | F35: 1 | G35: 0 | H35: 0 | I35: 0 | J35: 0 | K35: 1 | N35: haddock | O35: =B9 -> 4.2530649 | P35: =C9 -> 10.51529 | Q35: =SUM(D9:E9) -> 19.590381 | R35: =SUM(F9:G9) -> 19.302707 | S35: =SUM(H9:I9) -> 23.812588
A36: haddock | B36: 1 | C36: 1 | D36: 0 | E36: 0 | F36: 1 | G36: 0 | H36: 0 | I36: 0 | J36: 0 | K36: 1 | N36: yellowtailfl | O36: =B10 -> 3.9070123 | P36: =C10 -> 6.6463913 | Q36: =D10 -> 7.4657787 | R36: =E10 -> 8.9445013 | S36: =SUM(F10:G10) -> 22.156679
A37: yellowtailfl | B37: 1 | C37: 0 | D37: 0 | E37: 0 | F37: 0 | G37: 0 | H37: 0 | I37: 0 | J37: 0 | K37: 1 | N37: winterfl | O37: =B11 -> 1.9002648 | P37: =C11 -> 2.8288027 | Q37: =D11 -> 3.1164227 | R37: =E11 -> 3.7002457 | S37: =F11 -> 5.300677
A38: winterfl | B38: 1 | C38: 0 | D38: 0 | E38: 0 | F38: 0 | G38: 0 | H38: 0 | I38: 0 | J38: 0 | K38: 1 | N38: Amackerel | O38: =B12 -> 5.678337 | P38: =C12 -> 7.2383546 | Q38: =D12 -> 6.5280456 | R38: =E12 -> 5.8381126 | S38: =F12 -> 5.2898121
A39: Amackerel | B39: 1 | C39: 1 | D39: 0 | E39: 1 | F39: 0 | G39: 0 | H39: 0 | I39: 0 | J39: 1 | K39: 1 | N39: silverhake | O39: =B13 -> 4.4434732 | P39: =C13 -> 5.0468111 | Q39: =D13 -> 3.6543024 | R39: =E13 -> 2.5206962 | S39: =SUM(F13:H13) -> 3.315531
A40: silverhake | B40: 1 | C40: 1 | D40: 0 | E40: 1 | F40: 1 | G40: 0 | H40: 0 | I40: 0 | J40: 1 | K40: 1 | N40: goosefish | O40: =SUM(B14:C14) -> 0.34628021 | P40: =SUM(D14:E14) -> 0.352353 | Q40: =SUM(F14:G14) -> 0.29119758 | R40: =SUM(H14:J14) -> 0.30855819 | S40: =SUM(K14:N14) -> 0.134359
...

Sheet just10_newset_hydra_sim_MAB
B1: 9.8765333 | C1: 9.8765333 | D1: 9.8765333 | E1: 9.8765333 | F1: 9.8765333 | G1: 9.8765333 | H1: 9.8765333 | I1: 9.8765333 | J1: 9.8765333 | K1: 9.8765333 | L1: 9.8765333 | M1: 9.8765333 | N1: 9.8765333 | O1: 9.8765333 | P1: 9.8765333 | Q1: binwidth | R1: max Linf determined n size classes, all other in same
A2: init n at size | B2: 10 | C2: 20 | D2: 30 | E2: 40 | F2: 50 | G2: 60 | H2: 70 | I2: 80 | J2: 90 | K2: 100 | L2: 110 | M2: 120 | N2: 130 | O2: 140 | P2: 150 | Q2: use | R2: =148*1.001 -> 148.148 | S2: maxsize
A3: spinydog | B3: 0.66268858 | C3: 0.78275415 | D3: 0.6947107 | E3: 0.61053492 | F3: 0.52648703 | G3: 0.44055388 | H3: 0.35183219 | I3: 0.26060896 | J3: 0.16915631 | K3: 0.085657368 | L3: 0.014235365 | M3: 0 | N3: 0 | O3: 0 | P3: 0 | Q3: 1 | R3: 15 | S3: nsc | T3: n size classes
A4: littleskate | B4: 2.6402269 | C4: 4.7836717 | D4: 5.3512422 | E4: 6.3066725 | F4: 8.5388107 | G4: 11.161203 | H4: 0 | I4: 0 | J4: 0 | K4: 0 | L4: 0 | M4: 0 | N4: 0 | O4: 0 | P4: 0 | Q4: 1 | R4: =R2/R3 -> 9.8765333 | S4: 10 cm wide bins (approx)
A5: Aherring | B5: 80.697299 | C5: 85.853259 | D5: 58.989363 | E5: 30.434226 | F5: 0 | G5: 0 | H5: 0 | I5: 0 | J5: 0 | K5: 0 | L5: 0 | M5: 0 | N5: 0 | O5: 0 | P5: 0 | Q5: 1
A6: summerfl | B6: 0.0018852206 | C6: 0.0039069684 | D6: 0.0038549237 | E6: 0.003832133 | F6: 0.0038114598 | G6: 0.0037756335 | H6: 0.00370799 | I6: 0.0035849627 | J6: 0.0033785349 | K6: 0.0030581133 | L6: 0.0025956259 | M6: 0.0019734295 | N6: 0.0012000765 | O6: 0.0005287084 | P6: 0
A7: bluefish
A8: stripedbass
A9: butterfish
A10: Amackerel | B10: 5.678337 | C10: 7.2383546 | D10: 6.5280456 | E10: 5.8381126 | F10: 5.2898121 | G10: 0 | H10: 0 | I10: 0 | J10: 0 | K10: 0 | L10: 0 | M10: 0 | N10: 0 | O10: 0 | P10: 0 | Q10: 1
A11: silverhake | B11: 4.4434732 | C11: 5.0468111 | D11: 3.6543024 | E11: 2.5206962 | F11: 1.6896202 | G11: 1.0732097 | H11: 0.5527011 | I11: 0 | J11: 0 | K11: 0 | L11: 0 | M11: 0 | N11: 0 | O11: 0 | P11: 0 | Q11: 1 | X11: a | Y11: b
A12: goosefish | B12: 0.14683387 | C12: 0.19944634 | D12: 0.18371622 | E12: 0.16863678 | F12: 0.15346564 | G12: 0.13773194 | H12: 0.12109972 | I12: 0.10330729 | J12: 0.084151179 | K12: 0.063570465 | L12: 0.042037881 | M12: 0.021529943 | N12: 0.0072207089 | O12: 0 | P12: 0 | Q12: 1 | U12: need to fit to maturity data | X12: propmat=1/(1+exp(-(mat_nu+mat_omega*lbinmidpt)))
N13: binwidth | U13: used as first approximations | X13: mat dat Obrien et al 1993 (avg male and female)
A14: params | B14: vonB_k | C14: Linf | D14: L50mat | E14: kappamat | F14: lwt_a | G14: lwt_b | H14: maxSSB | I14: fished? | J14: inMSprod | K14: maxsize | L14: maxbin | M14: use | T14: L50matbin | U14: mat_nu | V14: mat_omega | X14: mat_nu | Y14: mat_omega | AA14: L50mat
A15: spinydog | B15: 0.1 | C15: 99.99 | D15: 79.99 | E15: 0.587 | F15: 0.003 | G15: 3.122 | H15: 16.125 | I15: 1 | J15: 1 | K15: =C15*1.01 -> 100.9899 | L15: =SUM(N15:R15) -> 110 | M15: 1 | N15: 20 | O15: 20 | P15: 20 | Q15: 20 | R15: 30 | T15: 4 | U15: -5 | V15: 0.1 | W15: spinydog
A16: littleskate | B16: 0.352 | C16: 53 | D16: 49.99 | E16: 0.587 | F16: 0.005 | G16: 3.141 | H16: 24.51 | I16: 1 | J16: agg | K16: =C16*1.01 -> 53.53 | L16: =SUM(N16:R16) -> 60 | M16: 1 | N16: 10 | O16: 10 | P16: 10 | Q16: 10 | R16: 20 | T16: 5 | U16: -5 | V16: 0.1 | W16: littleskate
A17: Aherring | B17: 0.28 | C17: 34.99 | D17: 25 | E17: 0.587 | F17: 0.01 | G17: 2.99 | H17: 101.91 | I17: 1 | J17: 1 | K17: =C17*1.01 -> 35.3399 | L17: =SUM(N17:R17) -> 40 | M17: 1 | N17: 5 | O17: 5 | P17: 10 | Q17: 10 | R17: 10 | T17: 5 | U17: -5 | V17: 0.2 | W17: Aherring | X17: =AVERAGE(-28.484,-40.461) -> -34.4725 | Y17: =AVERAGE(1.123,1.597) -> 1.36 | Z17: All | AA17: =AVERAGE(25.4,25.3) -> 25.35
A18: summerfl | B18: 0.173 | C18: 137 | D18: 26 | E18: 0.306 | F18: 0.007 | G18: 3.278 | H18: 0.43 | I18: 1 | J18: 0 | K18: =C18*1.01 -> 138.37 | L18: =SUM(N18:R18) -> 140 | M18: 1 | N18: 20 | O18: 20 | P18: 20 | Q18: 40 | R18: 40 | T18: 3 | U18: -5 | V18: 0.16 | W18: summerfl
A19: bluefish | L19: =SUM(N19:R19) -> 0 | M19: 1 | T19: 3 | U19: -5 | V19: 0.13 | W19: bluefish
A20: stripedbass | L20: =SUM(N20:R20) -> 0 | M20: 1 | T20: 3 | U20: -5 | V20: 0.2 | W20: stripedbass
A21: butterfish | L21: =SUM(N21:R21) -> 0 | M21: 1 | T21: 3 | U21: -5 | V21: 0.2 | W21: butterfish
A22: Amackerel | B22: 0.243 | C22: 46.1 | D22: 29.99 | E22: 0.641 | F22: 0.007 | G22: 3.319 | H22: 23.87 | I22: 1 | J22: 1 | K22: =C22*1.01 -> 46.561 | L22: =SUM(N22:R22) -> 50 | M22: 1 | N22: 10 | O22: 10 | P22: 10 | Q22: 10 | R22: 10 | T22: 3 | U22: -5 | V22: 0.2 | W22: Amackerel | X22: =AVERAGE(-16.475,-17.102) -> -16.7885 | Y22: =AVERAGE(0.641,0.658) -> 0.6495 | Z22: All | AA22: =AVERAGE(25.7,26) -> 25.85
A23: silverhake | B23: 0.18 | C23: 65.4 | D23: 23 | E23: 0.587 | F23: 0.007 | G23: 3.05 | H23: 25.8 | I23: 1 | J23: 0 | K23: =C23*1.01 -> 66.054 | L23: =SUM(N23:R23) -> 70 | M23: 1 | N23: 10 | O23: 10 | P23: 10 | Q23: 20 | R23: 20 | T23: 3 | U23: -5 | V23: 0.2 | W23: silverhake | X23: =AVERAGE(-11.963, -14.369) -> -13.166 | Y23: =AVERAGE(0.519, 0.646) -> 0.5825 | Z23: GOMNGB | AA23: =AVERAGE(23.1, 22.3) -> 22.7 | AB23: silver hake stock also splits GB in half. Using northern which includes GOM
A24: goosefish | B24: 0.108 | C24: 126 | D24: 49 | E24: 0.587 | F24: 0.02 | G24: 2.897 | H24: 6.45 | I24: 1 | J24: 0 | K24: =C24*1.01 -> 127.26 | L24: =SUM(N24:R24) -> 130 | M24: 1 | N24: 20 | O24: 20 | P24: 20 | Q24: 30 | R24: 40 | T24: 2 | U24: -5 | V24: 0.3 | W24: goosefish | X24: =AVERAGE(-9.765, -11.571) -> -10.668 | Y24: =AVERAGE(0.252,0.325) -> 0.2885 | Z24: NMA | AA24: =AVERAGE(38.8, 35.6) -> 37.2 | AB24: Richards et al 2008 | AD24: averaging M and F probably makes no sense
B25: *use my fitted parameters instead--see MABlenage_growthpars.csv | AB25: goosefish >70 cm all F? (size specific sex ratio needed in code?)
O26: for smaller bins, divide in half to approximate | X26: used these from Obrien | AB26: also, goosefish stock structure splits GB in half. Awesome.
O27: Initial n at size (sum bins above assuming they are 10 cm) | AB27: using Northern goosefish stock info (includes GOM).
A28: foodweb | B28: preds-> | O28: bin1 | P28: bin2 | Q28: bin3 | R28: bin4 | S28: bin5
A29: prey | B29: spinydog | C29: littleskate | D29: Aherring | E29: summerfl | F29: bluefish | G29: stripedbass | H29: butterfish | I29: Amackerel | J29: silverhake | K29: goosefish | N29: spinydog | O29: =SUM(B3:C3) -> 1.4454427 | P29: =SUM(D3:E3) -> 1.3052456 | Q29: =SUM(F3:G3) -> 0.96704091 | R29: =SUM(H3:I3) -> 0.61244115 | S29: =SUM(J3:L3) -> 0.26904904
A30: spinydog | B30: 1 | C30: 0 | D30: 0 | I30: 0 | J30: 0 | K30: 1 | N30: littleskate | O30: =SUM(#REF!) -> #REF! | P30: =SUM(#REF!) -> #REF! | Q30: =SUM(#REF!) -> #REF! | R30: =SUM(#REF!) -> #REF! | S30: =SUM(#REF!) -> #REF!
A31: littleskate | N31: Aherring | O31: =B5/2 -> 40.34865 | P31: =B5/2 -> 40.34865 | Q31: =C5 -> 85.853259 | R31: =D5 -> 58.989363 | S31: =E5 -> 30.434226
A32: Aherring | B32: 1 | C32: 1 | D32: 0 | I32: 0 | J32: 1 | K32: 1 | N32: summerfl | O32: =#REF!+#REF! -> #REF! | P32: =#REF!+#REF! -> #REF! | Q32: =SUM(#REF!) -> #REF! | R32: =SUM(#REF!) -> #REF! | S32: =SUM(#REF!) -> #REF!
A33: summerfl | N33: bluefish | O33: =#REF! -> #REF! | P33: =#REF! -> #REF! | Q33: =SUM(#REF!) -> #REF! | R33: =SUM(#REF!) -> #REF! | S33: =SUM(#REF!) -> #REF!
A34: bluefish | N34: stripedbass | O34: =#REF! -> #REF! | P34: =#REF! -> #REF! | Q34: =#REF! -> #REF! | R34: =#REF! -> #REF! | S34: =SUM(#REF!) -> #REF!
A35: stripedbass | N35: butterfish | O35: =#REF! -> #REF! | P35: =#REF! -> #REF! | Q35: =#REF! -> #REF! | R35: =#REF! -> #REF! | S35: =#REF! -> #REF!
A36: butterfish | N36: Amackerel | O36: =B10 -> 5.678337 | P36: =C10 -> 7.2383546 | Q36: =D10 -> 6.5280456 | R36: =E10 -> 5.8381126 | S36: =F10 -> 5.2898121
A37: Amackerel | B37: 1 | C37: 1 | D37: 0 | I37: 0 | J37: 1 | K37: 1 | N37: silverhake | O37: =B11 -> 4.4434732 | P37: =C11 -> 5.0468111 | Q37: =D11 -> 3.6543024 | R37: =SUM(E11:F11) -> 4.2103164 | S37: =SUM(G11:H11) -> 1.6259108
A38: silverhake | B38: 1 | C38: 1 | D38: 0 | I38: 0 | J38: 1 | K38: 1 | N38: goosefish | O38: =SUM(B12:C12) -> 0.34628021 | P38: =SUM(D12:E12) -> 0.352353 | Q38: =SUM(F12:G12) -> 0.29119758 | R38: =SUM(H12:J12) -> 0.30855819 | S38: =SUM(K12:N12) -> 0.134359
A39: goosefish | B39: 0 | C39: 0 | D39: 0 | I39: 0 | J39: 0 | K39: 1
N40: N_mult | O40: 3046527 | P40: convert catch per tow to total N (from Jason's data) used in LeMANS
...

Sheet biomass Atlantis newsimGB
B1: spinydog | C1: winterskate | D1: Aherring | E1: Acod | F1: haddock | G1: yellowtailfl | H1: winterfl | I1: Amackerel | J1: silverhake | K1: goosefish
A2: relBio | B2: Spiny Dogfish | C2: Skates and rays | D2: Herring | E2: Cod | F2: Haddock | G2: YT | H2: Other demersal flatfish | I2: Mackerel | J2: Silver hake | K2: Goosefish | M2: initial bio from my mod | U2: placeholders
A3: Year | B3: RelSHB | C3: RelSSK | D3: RelFPS | E3: RelFDS | F3: RelFDO | G3: RelFDF | H3: RelFVB | I3: RelFPL | J3: RelFDB | K3: RelFDD | M3: spinydog | N3: winterskate | O3: Aherring | P3: Acod | Q3: haddock | R3: yellowtailfl | S3: winterfl | T3: Amackerel | U3: silverhake | V3: goosefish
A4: 1964 | B4: 1 | C4: 1 | D4: 1 | E4: 1 | F4: 1 | G4: 1 | H4: 1 | I4: 1 | J4: 1 | K4: 1 | M4: 322944 | N4: 9413770 | O4: 2994860 | P4: 2778160 | Q4: 15591200 | R4: 4914660 | S4: 1363490 | T4: 2136940 | U4: 5000000 | V4: 500000 | X4: 322944 | Y4: 318582.96 | Z4: 313505.32 | AA4: 311187.22 | AB4: 313237.27 | AC4: 321777.2 | AD4: 335764.23 | AE4: 355575.23 | AF4: 391881.24 | AG4: 420356.83 | AH4: 453098.18 | AI4: 489544.35 | AJ4: 526790.45 | AK4: 564224.18 | AL4: 603763.18 | AM4: 644112.13 | AN4: 685405.04 | AO4: 717264.44 | AP4: 744810.27 | AQ4: 767269.73 | AR4: 789731.13 | AS4: 979954.84 | AT4: 985479.76 | AU4: 1000515.4 | AV4: 1023820.6 | AW4: 1049917.4 | AX4: 1078689.5 | AY4: 1224782.9 | AZ4: 1201531.2 | BA4: 1187721.2 | BB4: 1173336 | BC4: 1164290.9 | BD4: 1156423.7 | BE4: 1203591.6 | BF4: 1187939.5 | BG4: 1174918.7 | BH4: 1164941.4 | BI4: 1200004.7 | BJ4: 1189195.4 | BK4: 1184021.9 | BL4: 1294204.9 | BM4: 1256708.2 | BN4: 1225214.3 | BO4: 1195731.5 | BP4: 1168301.3 | BQ4: 1144856.8 | BR4: 1123438.2 | BS4: 1104724.9 | BT4: 1093997 | BU4: 1076095.9 | BV4: 1134128 | BW4: 1138306.2
A5: 1965 | B5: 0.986496 | C5: 1.307166 | D5: 0.869667 | E5: 0.994792 | F5: 0.541689 | G5: 0.72628 | H5: 1.043081 | I5: 1.244889 | J5: 1.052892 | K5: 1.066374 | M5: =B5*M$4 -> 318582.96 | N5: =C5*N$4 -> 12305360 | O5: =D5*O$4 -> 2604530.9 | P5: =E5*P$4 -> 2763691.3 | Q5: =F5*Q$4 -> 8445581.5 | R5: =G5*R$4 -> 3569419.3 | S5: =H5*S$4 -> 1422230.5 | T5: =I5*T$4 -> 2660253.1 | ... V5: =K5*V$4 -> 533187 | X5: 9413770 | Y5: 12305360 | Z5: 14523527 | AA5: 16346230 | AB5: 17538089 | AC5: 18730475 | AD5: 19930617 | AE5: 20381857 | AF5: 21123267 | AG5: 21908064 | AH5: 21841161 | AI5: 22158913 | AJ5: 22389485 | AK5: 21541869 | AL5: 21308407 | AM5: 21106746 | AN5: 19753413 | AO5: 19068476 | AP5: 18336452 | AQ5: 16946255 | AR5: 16085422 | AS5: 15539141 | AT5: 14373547 | AU5: 13589342 | AV5: 12868605 | AW5: 12205122 | AX5: 11590940 | AY5: 11095728 | AZ5: 10650485 | BA5: 10228071 | BB5: 9914450.8 | BC5: 9593714.2 | BD5: 9226765.5 | BE5: 8993661.7 | BF5: 8695970 | BG5: 8469437.1 | BH5: 8215500.6 | BI5: 8037542.7 | BJ5: 7923579.6 | BK5: 7859274.2 | BL5: 7793980.3 | BM5: 7766567.4 | BN5: 7730183.1 | BO5: 7673258.1 | BP5: 7680214.8 | BQ5: 7663712.5 | BR5: 7639406.1 | BS5: 7647605.5 | BT5: 7695455.7 | BU5: 7708465.6 | BV5: 7723009.8 | BW5: 7760928.5
A6: 1966 | B6: 0.970773 | C6: 1.542796 | D6: 0.715139 | E6: 1.018937 | F6: 0.441508 | G6: 0.75197 | H6: 0.938271 | I6: 0.974857 | J6: 1.005508 | K6: 1.255846 | M6: =B6*M$4 -> 313505.32 | N6: =C6*N$4 -> 14523527 | O6: =D6*O$4 -> 2141741.2 | P6: =E6*P$4 -> 2830770 | Q6: =F6*Q$4 -> 6883639.5 | R6: =G6*R$4 -> 3695676.9 | S6: =H6*S$4 -> 1279323.1 | T6: =I6*T$4 -> 2083210.9 | ... V6: =K6*V$4 -> 627923 | X6: 2994860 | Y6: 2604530.9 | Z6: 2141741.2 | AA6: 1696510.3 | AB6: 1316184.1 | AC6: 1020148.1 | AD6: 796743.57 | AE6: 668707.32 | AF6: 542216.41 | AG6: 473550.26 | AH6: 448896.57 | AI6: 493717.65 | AJ6: 397879.13 | AK6: 340716.24 | AL6: 668887.01 | AM6: 1043678.8 | AN6: 1353107.7 | AO6: 1528923.9 | AP6: 1662839.1 | AQ6: 2168901.6 | AR6: 2146757.6 | AS6: 2110259.2 | AT6: 2066905.6 | AU6: 1997122.4 | AV6: 1918926.6 | AW6: 1844720 | AX6: 1774274.9 | AY6: 1854537.1 | AZ6: 1770558.2 | BA6: 1704440.7 | BB6: 2202171.5 | BC6: 2420113.4 | BD6: 2192195.6 | BE6: 2768020.3 | BF6: 2431449 | BG6: 2208835 | BH6: 1989204 | BI6: 2273224.5 | BJ6: 2071026.6 | BK6: 1827409.7 | BL6: 2549296.7 | BM6: 2640433.3 | BN6: 2173768.2 | BO6: 1805002.1 | BP6: 1732532.5 | BQ6: 1456583.1 | BR6: 1298397.6 | BS6: 1354090 | BT6: 1218542.6 | BU6: 1132961.5 | BV6: 1077122.4 | BW6: 1102773.3
A7: 1967 | B7: 0.963595 | C7: 1.736417 | D7: 0.566474 | E7: 1.122334 | F7: 0.379628 | G7: 0.714927 | H7: 0.863131 | I7: 1.208799 | J7: 0.896164 | K7: 1.517069 | M7: =B7*M$4 -> 311187.22 | N7: =C7*N$4 -> 16346230 | O7: =D7*O$4 -> 1696510.3 | P7: =E7*P$4 -> 3118023.4 | Q7: =F7*Q$4 -> 5918856.1 | R7: =G7*R$4 -> 3513623.1 | S7: =H7*S$4 -> 1176870.5 | T7: =I7*T$4 -> 2583130.9 | ... V7: =K7*V$4 -> 758534.5 | X7: 2778160 | Y7: 2763691.3 | Z7: 2830770 | AA7: 3118023.4 | AB7: 3595266.9 | AC7: 3788993.5 | AD7: 3674255.5 | AE7: 3550288.5 | AF7: 3392766.8 | AG7: 3219656.9 | AH7: 3066580.2 | AI7: 2912625.7 | AJ7: 2737093.2 | AK7: 2562230.3 | AL7: 2422916.7 | AM7: 2248162.1 | AN7: 2076421.8 | AO7: 1934455 | AP7: 1809640.6 | AQ7: 1682423.1 | AR7: 1565607.1 | AS7: 1472716.5 | AT7: 1384334.9 | AU7: 1304268.3 | AV7: 1208027.3 | AW7: 1118064.9 | AX7: 1049797.2 | AY7: 1021879.5 | AZ7: 996187.06 | BA7: 969111.11 | BB7: 964196.54 | BC7: 951633.7 | BD7: 933072.82 | BE7: 923235.35 | BF7: 902985.34 | BG7: 898395.82 | BH7: 904571.67 | BI7: 922382.46 | BJ7: 951800.39 | BK7: 991600.31 | BL7: 1033636.7 | BM7: 1077381.6 | BN7: 1094595 | BO7: 1123754.6 | BP7: 1158401 | BQ7: 1212525.2 | BR7: 1254172.6 | BS7: 1280904 | BT7: 1297075.7 | BU7: 1323815.5 | BV7: 1340320.5 | BW7: 1342131.9
A8: 1968 | B8: 0.969943 | C8: 1.863025 | D8: 0.439481 | E8: 1.294118 | F8: 0.334951 | G8: 0.649541 | H8: 0.793899 | I8: 1.322042 | J8: 0.785247 | K8: 1.686751 | M8: =B8*M$4 -> 313237.27 | N8: =C8*N$4 -> 17538089 | O8: =D8*O$4 -> 1316184.1 | P8: =E8*P$4 -> 3595266.9 | Q8: =F8*Q$4 -> 5222288 | R8: =G8*R$4 -> 3192273.2 | S8: =H8*S$4 -> 1082473.3 | T8: =I8*T$4 -> 2825124.4 | ... V8: =K8*V$4 -> 843375.5 | X8: 15591200 | Y8: 8445581.5 | Z8: 6883639.5 | AA8: 5918856.1 | AB8: 5222288 | AC8: 4622572.5 | AD8: 4177272.3 | AE8: 3782799.3 | AF8: 3462587.2 | AG8: 3199750.8 | AH8: 2969577.9 | AI8: 2769620.8 | AJ8: 2562865.9 | AK8: 2366401.2 | AL8: 2194211.9 | AM8: 2006930.4 | AN8: 1841819.6 | AO8: 1685845.3 | AP8: 1519315.7 | AQ8: 1346066.3 | AR8: 1166658.3 | AS8: 1020225.8 | AT8: 855224.09 | AU8: 720173.12 | AV8: 582471.64 | AW8: 472304.22 | AX8: 430130.03 | AY8: 411155.54 | AZ8: 389327.86 | BA8: 370041.54 | BB8: 342710.17 | BC8: 323673.31 | BD8: 301050.48 | BE8: 287829.14 | BF8: 267124.03 | BG8: 258782.74 | BH8: 259546.71 | BI8: 276478.75 | BJ8: 302874.65 | BK8: 346545.6 | BL8: 394847.14 | BM8: 433622.45 | BN8: 482953.01 | BO8: 538099.09 | BP8: 594398.91 | BQ8: 654471.8 | BR8: 713936.64 | BS8: 745711.5 | BT8: 788509.35 | BU8: 842049.53 | BV8: 878392.62 | BW8: 857859.01
A9: 1969 | B9: 0.996387 | C9: 1.989689 | D9: 0.340633 | E9: 1.36385 | F9: 0.296486 | G9: 0.619087 | H9: 0.755971 | I9: 0.967718 | J9: 0.689636 | K9: 1.70933 | M9: =B9*M$4 -> 321777.2 | N9: =C9*N$4 -> 18730475 | O9: =D9*O$4 -> 1020148.1 | P9: =E9*P$4 -> 3788993.5 | Q9: =F9*Q$4 -> 4622572.5 | R9: =G9*R$4 -> 3042602.1 | S9: =H9*S$4 -> 1030758.9 | T9: =I9*T$4 -> 2067955.3 | ... V9: =K9*V$4 -> 854665 | X9: 4914660 | Y9: 3569419.3 | Z9: 3695676.9 | AA9: 3513623.1 | AB9: 3192273.2 | AC9: 3042602.1 | AD9: 2900131 | AE9: 2759537.4 | AF9: 2587509.5 | AG9: 2513401.4 | AH9: 2359602 | AI9: 2226842.3 | AJ9: 2043972.7 | AK9: 1943792.3 | AL9: 1792332.3 | AM9: 1659130.2 | AN9: 1499836.3 | AO9: 1336590.9 | AP9: 1220177.4 | AQ9: 1099276.7 | AR9: 974208.48 | AS9: 864464.12 | AT9: 751584.21 | AU9: 664304.76 | AV9: 575998.15 | AW9: 517228.65 | AX9: 521243.92 | AY9: 540774.78 | AZ9: 529957.62 | BA9: 507232.23 | BB9: 506323.02 | BC9: 511517.81 | BD9: 487396.66 | BE9: 468755.36 | BF9: 469841.5 | BG9: 470524.63 | BH9: 492237.6 | BI9: 526443.64 | BJ9: 565947.67 | BK9: 611201.86 | BL9: 636001.24 | BM9: 647349.19 | BN9: 663803.47 | BO9: 689059.91 | BP9: 716930.94 | BQ9: 742295.5 | BR9: 768397.26 | BS9: 790945.72 | BT9: 803183.23 | BU9: 833482.1 | BV9: 845360.84 | BW9: 833722.92
A10: 1970 | B10: 1.039698 | C10: 2.117177 | D10: 0.266037 | E10: 1.32255 | F10: 0.267925 | G10: 0.590098 | H10: 0.692775 | I10: 0.712073 | J10: 0.608382 | K10: 1.725906 | M10: =B10*M$4 -> 335764.23 | N10: =C10*N$4 -> 19930617 | O10: =D10*O$4 -> 796743.57 | P10: =E10*P$4 -> 3674255.5 | Q10: =F10*Q$4 -> 4177272.3 | R10: =G10*R$4 -> 2900131 | S10: =H10*S$4 -> 944591.78 | T10: =I10*T$4 -> 1521657.3 | ... V10: =K10*V$4 -> 862953 | X10: 1363490 | Y10: 1422230.5 | Z10: 1279323.1 | AA10: 1176870.5 | AB10: 1082473.3 | AC10: 1030758.9 | AD10: 944591.78 | AE10: 897859.53 | AF10: 826456.28 | AG10: 765167.41 | AH10: 703410.86 | AI10: 648700.82 | AJ10: 580096.82 | AK10: 517803.05 | AL10: 458068.56 | AM10: 414293.71 | AN10: 377658.1 | AO10: 322050.88 | AP10: 303428.34 | AQ10: 295897.78 | AR10: 277219.33 | AS10: 243318.88 | AT10: 231144.28 | AU10: 226624.31 | AV10: 210239.25 | AW10: 195689.45 | AX10: 217203.96 | AY10: 226427.97 | AZ10: 195858.52 | BA10: 203399.98 | BB10: 199169.07 | BC10: 201838.79 | BD10: 196143.49 | BE10: 219414.17 | BF10: 197286.1 | BG10: 204249.44 | BH10: 198415.06 | BI10: 208915.3 | BJ10: 221993.9 | BK10: 232466.86 | BL10: 228546.83 | BM10: 252680.6 | BN10: 240331.47 | BO10: 243872.46 | BP10: 248249.26 | BQ10: 244715.09 | BR10: 252139.3 | BS10: 251893.87 | BT10: 252676.51 | BU10: 256330.67 | BV10: 262387.29 | BW10: 248136.09
A11: 1971 | B11: 1.101043 | C11: 2.165111 | D11: 0.223285 | E11: 1.277928 | F11: 0.242624 | G11: 0.561491 | H11: 0.658501 | I11: 0.760225 | J11: 0.533582 | K11: 1.748681 | M11: =B11*M$4 -> 355575.23 | N11: =C11*N$4 -> 20381857 | O11: =D11*O$4 -> 668707.32 | P11: =E11*P$4 -> 3550288.5 | Q11: =F11*Q$4 -> 3782799.3 | R11: =G11*R$4 -> 2759537.4 | S11: =H11*S$4 -> 897859.53 | T11: =I11*T$4 -> 1624555.2 | ... V11: =K11*V$4 -> 874340.5 | X11: 2136940 | Y11: 2660253.1 | Z11: 2083210.9 | AA11: 2583130.9 | AB11: 2825124.4 | AC11: 2067955.3 | AD11: 1521657.3 | AE11: 1624555.2 | AF11: 1544105.8 | AG11: 1414318.8 | AH11: 1305638.3 | AI11: 813131.31 | AJ11: 516919.38 | AK11: 436598.21 | AL11: 669578.09 | AM11: 1056394.2 | AN11: 1002190.7 | AO11: 905406.52 | AP11: 1099483.4 | AQ11: 1970538.6 | AR11: 2853338.5 | AS11: 2443469.1 | AT11: 3450339.7 | AU11: 2777447.2 | AV11: 2400255.9 | AW11: 2072301.8 | AX11: 2785817.6 | AY11: 2444118.7 | AZ11: 2015734.9 | BA11: 2787888.3 | BB11: 2100936.8 | BC11: 1829819 | BD11: 2535466.5 | BE11: 3130151.2 | BF11: 2542633.8 | BG11: 3428030 | BH11: 3328807.6 | BI11: 4009914.5 | BJ11: 3149511.9 | BK11: 3955657.6 | BL11: 2982027.1 | BM11: 3021793.4 | BN11: 3511015.9 | BO11: 2637640 | BP11: 3380942.5 | BQ11: 3960918.7 | BR11: 4553936.7 | BS11: 5237088.6 | BT11: 5793643.9 | BU11: 6420934.1 | BV11: 4921422 | BW11: 4925022.7
A12: 1972 | B12: 1.213465 | C12: 2.243869 | D12: 0.181049 | E12: 1.221228 | F12: 0.222086 | G12: 0.526488 | H12: 0.606133 | I12: 0.722578 | J12: 0.490403 | K12: 1.755773 | M12: =B12*M$4 -> 391881.24 | N12: =C12*N$4 -> 21123267 | O12: =D12*O$4 -> 542216.41 | P12: =E12*P$4 -> 3392766.8 | Q12: =F12*Q$4 -> 3462587.2 | R12: =G12*R$4 -> 2587509.5 | S12: =H12*S$4 -> 826456.28 | T12: =I12*T$4 -> 1544105.8 | ... V12: =K12*V$4 -> 877886.5 | X12: 5000000 | Y12: 5264460 | Z12: 5027540 | AA12: 4480820 | AB12: 3926235 | AC12: 3448180 | AD12: 3041910 | AE12: 2667910 | AF12: 2452015 | AG12: 2097655 | AH12: 1796295 | AI12: 1544535 | AJ12: 1298900 | AK12: 1030890 | AL12: 1465390 | AM12: 1955675 | AN12: 2325605 | AO12: 2452155 | AP12: 2443455 | AQ12: 2379600 | AR12: 2237180 | AS12: 2093985 | AT12: 1851325 | AU12: 1644920 | AV12: 1433840 | AW12: 1264085 | AX12: 1167880 | AY12: 1107045 | AZ12: 1068050 | BA12: 1035855 | BB12: 1021370 | BC12: 1004030 | BD12: 980235 | BE12: 981910 | BF12: 967180 | BG12: 986035 | BH12: 989970 | BI12: 1051535 | BJ12: 1112725 | BK12: 1179575 | BL12: 1248480 | BM12: 1314330 | BN12: 1415845 | BO12: 1477605 | BP12: 1519510 | BQ12: 1621495 | BR12: 1702530 | BS12: 1769795 | BT12: 1794900 | BU12: 1838910 | BV12: 1904070 | BW12: 1907075
A13: 1973 | B13: 1.30164 | C13: 2.327236 | D13: 0.158121 | E13: 1.158917 | F13: 0.205228 | G13: 0.511409 | H13: 0.561183 | I13: 0.661843 | J13: 0.419531 | K13: 1.767157 | M13: =B13*M$4 -> 420356.83 | N13: =C13*N$4 -> 21908064 | O13: =D13*O$4 -> 473550.26 | P13: =E13*P$4 -> 3219656.9 | Q13: =F13*Q$4 -> 3199750.8 | R13: =G13*R$4 -> 2513401.4 | S13: =H13*S$4 -> 765167.41 | T13: =I13*T$4 -> 1414318.8 | ... V13: =K13*V$4 -> 883578.5 | X13: 500000 | Y13: 533187 | Z13: 627923 | AA13: 758534.5 | AB13: 843375.5 | AC13: 854665 | AD13: 862953 | AE13: 874340.5 | AF13: 877886.5 | AG13: 883578.5 | AH13: 877285.5 | AI13: 885015.5 | AJ13: 871092 | AK13: 870090.5 | AL13: 875358 | AM13: 889216 | AN13: 884812 | AO13: 885856 | AP13: 872234.5 | AQ13: 880019 | AR13: 870902 | AS13: 865407 | AT13: 864961 | AU13: 866824 | AV13: 851914.5 | AW13: 844535.5 | AX13: 825003.5 | AY13: 824347 | AZ13: 820541.5 | BA13: 819458.5 | BB13: 809473.5 | BC13: 820131 | BD13: 816845.5 | BE13: 814717.5 | BF13: 809854.5 | BG13: 812368.5 | BH13: 804822 | BI13: 812431.5 | BJ13: 809281.5 | BK13: 804658 | BL13: 805165 | BM13: 813186 | BN13: 803146 | BO13: 804741 | BP13: 796595 | BQ13: 798917 | BR13: 795012.5 | BS13: 808069 | BT13: 796351 | BU13: 804116 | BV13: 790638 | BW13: 799271
A14: 1974 | B14: 1.403024 | C14: 2.320129 | D14: 0.149889 | E14: 1.103817 | F14: 0.190465 | G14: 0.480115 | H14: 0.51589 | I14: 0.610985 | J14: 0.359259 | K14: 1.754571 | M14: =B14*M$4 -> 453098.18 | N14: =C14*N$4 -> 21841161 | O14: =D14*O$4 -> 448896.57 | P14: =E14*P$4 -> 3066580.2 | Q14: =F14*Q$4 -> 2969577.9 | R14: =G14*R$4 -> 2359602 | S14: =H14*S$4 -> 703410.86 | T14: =I14*T$4 -> 1305638.3 | ... V14: =K14*V$4 -> 877285.5
A15: 1975 | B15: 1.51588 | C15: 2.353883 | D15: 0.164855 | E15: 1.048401 | F15: 0.17764 | G15: 0.453102 | H15: 0.475765 | I15: 0.380512 | J15: 0.308907 | K15: 1.770031 | M15: =B15*M$4 -> 489544.35 | N15: =C15*N$4 -> 22158913 | O15: =D15*O$4 -> 493717.65 | P15: =E15*P$4 -> 2912625.7 | Q15: =F15*Q$4 -> 2769620.8 | R15: =G15*R$4 -> 2226842.3 | S15: =H15*S$4 -> 648700.82 | T15: =I15*T$4 -> 813131.31 | ... V15: =K15*V$4 -> 885015.5
A16: 1976 | B16: 1.631213 | C16: 2.378376 | D16: 0.132854 | E16: 0.985218 | F16: 0.164379 | G16: 0.415893 | H16: 0.42545 | I16: 0.241897 | J16: 0.25978 | K16: 1.742184 | M16: =B16*M$4 -> 526790.45 | N16: =C16*N$4 -> 22389485 | O16: =D16*O$4 -> 397879.13 | P16: =E16*P$4 -> 2737093.2 | Q16: =F16*Q$4 -> 2562865.9 | R16: =G16*R$4 -> 2043972.7 | S16: =H16*S$4 -> 580096.82 | T16: =I16*T$4 -> 516919.38 | ... V16: =K16*V$4 -> 871092
A17: 1977 | B17: 1.747127 | C17: 2.288336 | D17: 0.113767 | E17: 0.922276 | F17: 0.151778 | G17: 0.395509 | H17: 0.379763 | I17: 0.20431 | J17: 0.206178 | K17: 1.740181 | M17: =B17*M$4 -> 564224.18 | N17: =C17*N$4 -> 21541869 | O17: =D17*O$4 -> 340716.24 | P17: =E17*P$4 -> 2562230.3 | Q17: =F17*Q$4 -> 2366401.2 | R17: =G17*R$4 -> 1943792.3 | S17: =H17*S$4 -> 517803.05 | T17: =I17*T$4 -> 436598.21 | ... V17: =K17*V$4 -> 870090.5
A18: 1978 | B18: 1.86956 | C18: 2.263536 | D18: 0.223345 | E18: 0.87213 | F18: 0.140734 | G18: 0.364691 | H18: 0.335953 | I18: 0.313335 | J18: 0.293078 | K18: 1.750716 | M18: =B18*M$4 -> 603763.18 | N18: =C18*N$4 -> 21308407 | O18: =D18*O$4 -> 668887.01 | P18: =E18*P$4 -> 2422916.7 | Q18: =F18*Q$4 -> 2194211.9 | R18: =G18*R$4 -> 1792332.3 | S18: =H18*S$4 -> 458068.56 | T18: =I18*T$4 -> 669578.09 | ... V18: =K18*V$4 -> 875358
A19: 1979 | B19: 1.994501 | C19: 2.242114 | D19: 0.34849 | E19: 0.809227 | F19: 0.128722 | G19: 0.337588 | H19: 0.303848 | I19: 0.494349 | J19: 0.391135 | K19: 1.778432 | M19: =B19*M$4 -> 644112.13 | N19: =C19*N$4 -> 21106746 | O19: =D19*O$4 -> 1043678.8 | P19: =E19*P$4 -> 2248162.1 | Q19: =F19*Q$4 -> 2006930.4 | R19: =G19*R$4 -> 1659130.2 | S19: =H19*S$4 -> 414293.71 | T19: =I19*T$4 -> 1056394.2 | ... V19: =K19*V$4 -> 889216
A20: 1980 | B20: 2.122365 | C20: 2.098353 | D20: 0.45181 | E20: 0.747409 | F20: 0.118132 | G20: 0.305176 | H20: 0.276979 | I20: 0.468984 | J20: 0.465121 | K20: 1.769624 | M20: =B20*M$4 -> 685405.04 | N20: =C20*N$4 -> 19753413 | O20: =D20*O$4 -> 1353107.7 | P20: =E20*P$4 -> 2076421.8 | Q20: =F20*Q$4 -> 1841819.6 | R20: =G20*R$4 -> 1499836.3 | S20: =H20*S$4 -> 377658.1 | T20: =I20*T$4 -> 1002190.7 | ... V20: =K20*V$4 -> 884812
A21: 1981 | B21: 2.221018 | C21: 2.025594 | D21: 0.510516 | E21: 0.696308 | F21: 0.108128 | G21: 0.27196 | H21: 0.236196 | I21: 0.423693 | J21: 0.490431 | K21: 1.771712 | M21: =B21*M$4 -> 717264.44 | N21: =C21*N$4 -> 19068476 | O21: =D21*O$4 -> 1528923.9 | P21: =E21*P$4 -> 1934455 | Q21: =F21*Q$4 -> 1685845.3 | R21: =G21*R$4 -> 1336590.9 | S21: =H21*S$4 -> 322050.88 | T21: =I21*T$4 -> 905406.52 | ... V21: =K21*V$4 -> 885856
A22: 1982 | B22: 2.306314 | C22: 1.947833 | D22: 0.555231 | E22: 0.651381 | F22: 0.097447 | G22: 0.248273 | H22: 0.222538 | I22: 0.514513 | J22: 0.488691 | K22: 1.744469 | M22: =B22*M$4 -> 744810.27 | N22: =C22*N$4 -> 18336452 | O22: =D22*O$4 -> 1662839.1 | P22: =E22*P$4 -> 1809640.6 | Q22: =F22*Q$4 -> 1519315.7 | R22: =G22*R$4 -> 1220177.4 | S22: =H22*S$4 -> 303428.34 | T22: =I22*T$4 -> 1099483.4 | ... V22: =K22*V$4 -> 872234.5
A23: 1983 | B23: 2.37586 | C23: 1.800156 | D23: 0.724208 | E23: 0.605589 | F23: 0.086335 | G23: 0.223673 | H23: 0.217015 | I23: 0.922131 | J23: 0.47592 | K23: 1.760038 | M23: =B23*M$4 -> 767269.73 | N23: =C23*N$4 -> 16946255 | O23: =D23*O$4 -> 2168901.6 | P23: =E23*P$4 -> 1682423.1 | Q23: =F23*Q$4 -> 1346066.3 | R23: =G23*R$4 -> 1099276.7 | S23: =H23*S$4 -> 295897.78 | T23: =I23*T$4 -> 1970538.6 | ... V23: =K23*V$4 -> 880019
A24: 1984 | B24: 2.445412 | C24: 1.708712 | D24: 0.716814 | E24: 0.563541 | F24: 0.074828 | G24: 0.198225 | H24: 0.203316 | I24: 1.335245 | J24: 0.447436 | K24: 1.741804 | M24: =B24*M$4 -> 789731.13 | N24: =C24*N$4 -> 16085422 | O24: =D24*O$4 -> 2146757.6 | P24: =E24*P$4 -> 1565607.1 | Q24: =F24*Q$4 -> 1166658.3 | R24: =G24*R$4 -> 974208.48 | S24: =H24*S$4 -> 277219.33 | T24: =I24*T$4 -> 2853338.5 | ... V24: =K24*V$4 -> 870902
A25: 1985 | B25: 3.034442 | C25: 1.650682 | D25: 0.704627 | E25: 0.530105 | F25: 0.065436 | G25: 0.175895 | H25: 0.178453 | I25: 1.143443 | J25: 0.418797 | K25: 1.730814 | M25: =B25*M$4 -> 979954.84 | N25: =C25*N$4 -> 15539141 | O25: =D25*O$4 -> 2110259.2 | P25: =E25*P$4 -> 1472716.5 | Q25: =F25*Q$4 -> 1020225.8 | R25: =G25*R$4 -> 864464.12 | S25: =H25*S$4 -> 243318.88 | T25: =I25*T$4 -> 2443469.1 | ... V25: =K25*V$4 -> 865407
... A55: 2014.14 | B55: 3.524779 | C55: 0.824423 | D55: 0.368222 | E55: 0.483101 | F55: 0.055022 | G55: 0.16964 | H55: 0.181986 | I55: 2.304708 | J55: 0.381415 | K55: 1.598542 | M55: =B55*M$4 -> 1138306.2 | N55: =C55*N$4 -> 7760928.5 | O55: =D55*O$4 -> 1102773.3 | P55: =E55*P$4 -> 1342131.9 | Q55: =F55*Q$4 -> 857859.01 | R55: =G55*R$4 -> 833722.92 | S55: =H55*S$4 -> 248136.09 | T55: =I55*T$4 -> 4925022.7 | ... V55: =K55*V$4 -> 799271
B56: SHB | C56: SSK | D56: FPS | E56: FDS | F56: FDO | G56: FDF | H56: FVB | I56: FPL | J56: FDC | K56: FBP

Sheet catch Atlantis newsimGB
B1: spinydog | C1: winterskate | D1: Aherring | E1: Acod | F1: haddock | G1: yellowtailfl | H1: winterfl | I1: Amackerel | J1: silverhake | K1: goosefish | M1: scale | N1: 1
B2: Spiny Dogfish | C2: Skates and rays | D2: Herring | E2: Cod | F2: Haddock | G2: YT | H2: Other demersal flatfish | I2: Mackerel | J2: Silver hake | K2: Goosefish | M2: catch/bio | X2: catch
A3: Year | B3: SHB | C3: SSK | D3: FPS | E3: FDS | F3: FDO | G3: FDF | H3: FVB | I3: FPL | J3: FDB | K3: FDD | M3: spinydog | N3: winterskate | O3: Aherring | P3: Acod | Q3: haddock | R3: yellowtailfl | S3: winterfl | T3: Amackerel | U3: silverhake | V3: goosefish | X3: spinydog | Y3: winterskate | Z3: Aherring | AA3: Acod | AB3: haddock | AC3: yellowtailfl | AD3: winterfl | AE3: Amackerel | AF3: silverhake | AG3: goosefish | AI3: 363.82489 | AJ3: 363.82489 | AK3: 382.0608 | AL3: 369.60931 | AM3: 434.65034 | AN3: 404.80209 | AO3: 450.56642 | AP3: 472.46796 | AQ3: 520.45974 | AR3: 589.58914 | AS3: 708.99684 | AT3: 786.78939 | AU3: 881.68898 | AV3: 1052.6269 | AW3: 1153.9554 | AX3: 1279.3766 | AY3: 1446.3901 | AZ3: 1602.7156 | BA3: 1706.1991 | BB3: 1799.8479 | BC3: 1881.8771 | BD3: 1971.0831 | BE3: 2335.857 | BF3: 2373.1879 | BG3: 2373.6759 | BH3: 2501.8112 | BI3: 2536.6546 | BJ3: 2700.2659 | BK3: 2944.7882 | BL3: 2932.5933 | BM3: 2795.1587 | BN3: 2789.8493 | BO3: 2868.7518 | BP3: 2733.9278 | BQ3: 2861.046 | BR3: 2885.6726 | BS3: 2971.1191 | BT3: 2939.5122 | BU3: 2873.086 | BV3: 2905.8942 | BW3: 2770.5026 | BX3: 3222.8973 | BY3: 3693.1138 | BZ3: 4137.1734 | CA3: 4343.8839 | CB3: 4059.6358 | CC3: 3797.9764 | CD3: 3870.8887 | CE3: 3822.2195 | CF3: 3678.5926 | CG3: 3957.6527
A4: 1964 | B4: 0 | C4: 0 | D4: 0 | E4: 0 | F4: 0 | G4: 0 | H4: 0 | I4: 0 | J4: 0 | K4: 0 | M4: =B4*$N$1/'biomass Atlantis newsimGB'!M4 -> 0 | N4: =C4*$N$1/'biomass Atlantis newsimGB'!N4 -> 0 | O4: =D4*$N$1/'biomass Atlantis newsimGB'!O4 -> 0 | P4: =E4*$N$1/'biomass Atlantis newsimGB'!P4 -> 0 | Q4: =F4*$N$1/'biomass Atlantis newsimGB'!Q4 -> 0 | R4: =G4*$N$1/'biomass Atlantis newsimGB'!R4 -> 0 | S4: =H4*$N$1/'biomass Atlantis newsimGB'!S4 -> 0 | T4: =I4*$N$1/'biomass Atlantis newsimGB'!T4 -> 0 | ... V4: =K4*$N$1/'biomass Atlantis newsimGB'!V4 -> 0 | X4: =B4*$N$1 -> 0 | Y4: =C4*$N$1 -> 0 | Z4: =D4*$N$1 -> 0 | AA4: =E4*$N$1 -> 0 | AB4: =F4*$N$1 -> 0 | AC4: =G4*$N$1 -> 0 | AD4: =H4*$N$1 -> 0 | AE4: =I4*$N$1 -> 0 | ... AG4: =K4*$N$1 -> 0 | AI4: 2156.8743 | AJ4: 2156.8743 | AK4: 2272.0033 | AL4: 2415.8337 | AM4: 2629.4383 | AN4: 2948.8153 | AO4: 3353.6251 | AP4: 3775.1407 | AQ4: 4190.7824 | AR4: 4678.7824 | AS4: 5148.3284 | AT4: 5571.3213 | AU4: 6130.0857 | AV4: 6646.9508 | AW4: 7046.4261 | AX4: 7586.0498 | AY4: 8037.6786 | AZ4: 8124.4333 | BA4: 8341.2514 | BB4: 8465.6323 | BC4: 8379.3062 | BD4: 8412.4726 | BE4: 8625.7778 | BF4: 8478.5393 | BG4: 8545.4085 | BH4: 8437.0611 | BI4: 7837.0772 | BJ4: 7460.6613 | BK4: 7225.8902 | BL4: 7001.0643 | BM4: 6764.8845 | BN4: 6620.3073 | BO4: 6497.6742 | BP4: 6273.5931 | BQ4: 6166.3686 | BR4: 5901.3353 | BS4: 5642.9171 | BT4: 5349.5453 | BU4: 5077.5734 | BV4: 4844.8994 | BW4: 4718.1857 | BX4: 4612.315 | BY4: 4489.5528 | BZ4: 4382.6154 | CA4: 4249.1755 | CB4: 4194.1054 | CC4: 4149.3931 | CD4: 4109.6048 | CE4: 4049.1942 | CF4: 3994.5309 | CG4: 3982.5566
